<?xml version="1.0"?>
<robot name="kuka_lwr" xmlns:xacro="http://www.ros.org/wiki/xacro">


	<!-- properties /-->
	<xacro:property name="M_PI" value="3.1415926535897931"/>
	<xacro:property name="velocity_scale" value="1"/>
	<xacro:property name="effort_scale" value="1"/>

	<xacro:property name="name" value="kuka_lwr"/>


	<link name="${name}_base_link">
		<visual>
			<origin xyz="0 0 0" rpy="0 0 ${M_PI}"/>
			<geometry>
				<mesh filename="package://lwr_description/meshes/lwr4plus/visual/base.dae"/>
			</geometry>
		</visual>
		<collision>
			<origin xyz="0 0 0.055" rpy="0 0 ${M_PI}"/>
			<geometry>
				<cylinder radius="0.07" length="0.11"/>
			</geometry>
		</collision>
	</link>

	<!-- Second segment of the arm. Joint along z-axis -->
	<joint name="Joint_1" type="revolute">
		<origin xyz="0 0 0.11" rpy="0 0 0"/>
		<axis xyz="0 0 1"/>
		<limit lower="${-170 * M_PI / 180}" upper="${170 * M_PI / 180}" effort="176" velocity="${velocity_scale * 110 * M_PI / 180}" />
		<dynamics friction="10.0" damping="1.0"/>
		<parent link="${name}_base_link"/>
		<child link="${name}_1_link"/>
	</joint>

	<link name="${name}_1_link">
		<visual>
			<origin xyz="0 0 -0.008" rpy="0 0 ${M_PI}"/>
			<geometry>
				<mesh filename="package://lwr_description/meshes/lwr4plus/visual/link_1.dae"/>
			</geometry>
		</visual>
		<collision>
			<origin xyz="0 0 0.0" rpy="0 0 0"/>
			<geometry>
				<sphere radius="0.07"/>
			</geometry>
		</collision>
		<collision>
			<origin xyz="0 0.06 0.2" rpy="0 0 0"/>
			<geometry>
				<sphere radius="0.07"/>
			</geometry>
		</collision>
		<collision>
			<origin xyz="0 0.03 0.1" rpy="-0.291 0 0"/>
			<geometry>
				<cylinder radius="0.07" length="0.208"/>
			</geometry>
		</collision>
	</link>

	<!-- Third segment of the arm. Joint along y-axis -->
	<joint name="Joint_2" type="revolute">
		<origin xyz="0 0 0.2005" rpy="0 0 0"/>
		<axis xyz="0 -1 0"/>
		<limit lower="${-120 * M_PI / 180}" upper="${120 * M_PI / 180}" effort="176" velocity="${velocity_scale * 110 * M_PI / 180}" />
		<dynamics friction="10.0" damping="1.0"/>
		<parent link="${name}_1_link"/>
		<child link="${name}_2_link"/>
	</joint>

	<link name="${name}_2_link">
		<visual>
			<origin xyz="0 0 0.0" rpy="0 0 ${M_PI}"/>
			<geometry>
				<mesh filename="package://lwr_description/meshes/lwr4plus/visual/link_2.dae"/>
			</geometry>
		</visual>
		<collision>
			<origin xyz="0 0 0.2" rpy="0 0 0"/>
			<geometry>
				<sphere radius="0.07"/>
			</geometry>
		</collision>
		<collision>
			<origin xyz="0 -0.06 0.0" rpy="0 0 0"/>
			<geometry>
				<sphere radius="0.07"/>
			</geometry>
		</collision>
		<collision>
			<origin xyz="0 -0.03 0.1" rpy="-0.291 0 0"/>
			<geometry>
				<cylinder radius="0.07" length="0.208"/>
			</geometry>
		</collision>
	</link>

	<!-- Fourth element of the arm. z-axis -->
	<joint name="Joint_3" type="revolute">
		<origin xyz="0 0 0.20" rpy="0 0 0"/>
		<axis xyz="0 0 1"/>
		<limit lower="${-170 * M_PI / 180}" upper="${170 * M_PI / 180}" effort="100" velocity="${velocity_scale * 128 * M_PI / 180}" />
		<dynamics friction="10.0" damping="1.0"/>
		<parent link="${name}_2_link"/>
		<child link="${name}_3_link"/>
	</joint>

	<link name="${name}_3_link">
		<visual>
			<origin xyz="0 0 -0.008" rpy="0 0 ${M_PI}"/>
			<geometry>
				<mesh filename="package://lwr_description/meshes/lwr4plus/visual/link_3.dae"/>
			</geometry>
		</visual>
		<collision>
			<origin xyz="0 0 0.0" rpy="0 0 0"/>
			<geometry>
				<sphere radius="0.07"/>
			</geometry>
		</collision>
		<collision>
			<origin xyz="0 -0.06 0.2" rpy="0 0 0"/>
			<geometry>
				<sphere radius="0.07"/>
			</geometry>
		</collision>
		<collision>
			<origin xyz="0 -0.03 0.1" rpy="0.291 0 0"/>
			<geometry>
				<cylinder radius="0.07" length="0.208"/>
			</geometry>
		</collision>
	</link>

	<!-- fifth element of the arm. x-axis -->
	<joint name="Joint_4" type="revolute">
		<origin xyz="0 0 0.20" rpy="0 0 0"/>
		<axis xyz="0 1 0"/>
		<limit lower="${-120 * M_PI / 180}" upper="${120 * M_PI / 180}" effort="100" velocity="${velocity_scale * 128 * M_PI / 180}" />
		<dynamics friction="10.0" damping="1.0"/>
		<parent link="${name}_3_link"/>
		<child link="${name}_4_link"/>
	</joint>

	<link name="${name}_4_link">
		<visual>
			<origin xyz="0 0 0.0" rpy="0 0 ${M_PI}"/>
			<geometry>
				<mesh filename="package://lwr_description/meshes/lwr4plus/visual/link_4.dae"/>
			</geometry>
		</visual>
		<collision>
		<origin xyz="0 0 0.2" rpy="0 0 0"/>
		<geometry>
			<sphere radius="0.07"/>
		</geometry>
		</collision>
		<collision>
			<origin xyz="0 0.06 0.0" rpy="0 0 0"/>
			<geometry>
				<sphere radius="0.07"/>
			</geometry>
		</collision>
		<collision>
			<origin xyz="0 0.03 0.1" rpy="0.291 0 0"/>
			<geometry>
				<cylinder radius="0.07" length="0.208"/>
			</geometry>
		</collision>
	</link>

	<!-- Sixth element of the arm. z-axis -->
	<joint name="Joint_5" type="revolute">
		<origin xyz="0 0 0.20" rpy="0 0 0"/>
		<axis xyz="0 0 1"/>
		<limit lower="${-170 * M_PI / 180}" upper="${170 * M_PI / 180}" effort="100" velocity="${velocity_scale * 204 * M_PI / 180}" />
		<dynamics friction="10.0" damping="1.0"/>
		<parent link="${name}_4_link"/>
		<child link="${name}_5_link"/>
	</joint>

	<link name="${name}_5_link">
		<visual>
			<origin xyz="0 0 -0.008" rpy="0 0 ${M_PI}"/>
			<geometry name="${name}_5_geom">
				<mesh filename="package://lwr_description/meshes/lwr4plus/visual/link_5.dae"/>
			</geometry>
		</visual>

		<collision>
			<origin xyz="0 0 0.0" rpy="0 0 0"/>
			<geometry>
				<sphere radius="0.07"/>
			</geometry>
		</collision>
		<collision>
			<origin xyz="0 0.04 0.19" rpy="0 0 0"/>
			<geometry>
				<sphere radius="0.07"/>
			</geometry>
		</collision>
		<collision>
			<origin xyz="0 0.02 0.095" rpy="-0.207 0 0"/>
			<geometry>
				<cylinder radius="0.07" length="0.198"/>
			</geometry>
		</collision>
	</link>

	<!-- Seventh element of the arm. z-axis -->
	<joint name="Joint_6" type="revolute">
		<origin xyz="0 0 0.19" rpy="0 0 0"/>
		<axis xyz="0 -1 0"/>
		<limit lower="${-120 * M_PI / 180}" upper="${120 * M_PI / 180}" effort="38" velocity="${velocity_scale * 184 * M_PI / 180}" />
		<dynamics friction="10.0" damping="1.0"/>
		<parent link="${name}_5_link"/>
		<child link="${name}_6_link"/>
	</joint>

	<link name="${name}_6_link">
		<visual>
			<origin xyz="0 0 0" rpy="0 0 ${M_PI}"/>
			<geometry>
				<mesh filename="package://lwr_description/meshes/lwr4plus/visual/link_6.dae"/>
			</geometry>
		</visual>
		<collision>
		<origin xyz="0 -0.01 0" rpy="0 0 ${M_PI}"/>
		<geometry>
			<sphere radius="0.08"/>
		</geometry>
		</collision>
	</link>

	<!-- Eighth element of the arm. z-axis -->
	<joint name="Joint_7" type="revolute">
		<origin xyz="0 0 0.078" rpy="0 0 0"/>
		<axis xyz="0 0 1"/>
		<limit lower="${-170 * M_PI / 180}" upper="${170 * M_PI / 180}" effort="38" velocity="${velocity_scale * 184 * M_PI / 180}" />
		<dynamics friction="10.0" damping="1.0"/>
		<parent link="${name}_6_link"/>
		<child link="${name}_7_link"/>
	</joint>

	<link name="${name}_7_link">
		<visual>
			<origin xyz="0 0 0" rpy="0 0 ${M_PI}"/>
			<geometry>
				<mesh filename="package://lwr_description/meshes/lwr4plus/visual/link_7.dae"/>
			</geometry>
		</visual>

		<collision>
		<origin xyz="0 0 0" rpy="0 0 ${M_PI}"/>
		<geometry>
			<cylinder radius="0.04" length="0.05"/>
		</geometry>
		</collision>
	</link>


</robot>