<?xml version="1.0"?>
<robot name="kuka_lwr" xmlns:xacro="http://www.ros.org/wiki/xacro">

	<!-- Constants /-->
	<xacro:property name="M_PI" value="3.1415926535897931"/>
	<xacro:property name="velocity_scale" value="1"/>
	<xacro:property name="effort_scale" value="1"/>
	<xacro:property name="name" value="kuka_lwr"/>

	<link name="${name}_base_link">
		<visual>
			<origin xyz="0 0 0" rpy="0 0 ${M_PI}"/>
			<geometry>
				<mesh filename="package://lwr_description/meshes/base.dae"/>
			</geometry>
		</visual>
	</link>

	<joint name="Joint_1" type="revolute">
		<origin xyz="0 0 0.11" rpy="0 0 0"/>
		<axis xyz="0 0 1"/>
		<limit lower="${-170 * M_PI / 180}" upper="${170 * M_PI / 180}" effort="176" velocity="${velocity_scale * 110 * M_PI / 180}" />
		<parent link="${name}_base_link"/>
		<child link="${name}_1_link"/>
	</joint>

	<link name="${name}_1_link">
		<visual>
			<origin xyz="0 0 -0.008" rpy="0 0 ${M_PI}"/>
			<geometry>
				<mesh filename="package://lwr_description/meshes/link_1.dae"/>
			</geometry>
		</visual>
	</link>

	<joint name="Joint_2" type="revolute">
		<origin xyz="0 0 0.2005" rpy="0 0 0"/>
		<axis xyz="0 -1 0"/>
		<limit lower="${-120 * M_PI / 180}" upper="${120 * M_PI / 180}" effort="176" velocity="${velocity_scale * 110 * M_PI / 180}" />
		<parent link="${name}_1_link"/>
		<child link="${name}_2_link"/>
	</joint>

	<link name="${name}_2_link">
		<visual>
			<origin xyz="0 0 0.0" rpy="0 0 ${M_PI}"/>
			<geometry>
				<mesh filename="package://lwr_description/meshes/link_2.dae"/>
			</geometry>
		</visual>
	</link>

	<joint name="Joint_3" type="revolute">
		<origin xyz="0 0 0.20" rpy="0 0 0"/>
		<axis xyz="0 0 1"/>
		<limit lower="${-170 * M_PI / 180}" upper="${170 * M_PI / 180}" effort="100" velocity="${velocity_scale * 128 * M_PI / 180}" />
		<parent link="${name}_2_link"/>
		<child link="${name}_3_link"/>
	</joint>

	<link name="${name}_3_link">
		<visual>
			<origin xyz="0 0 -0.008" rpy="0 0 ${M_PI}"/>
			<geometry>
				<mesh filename="package://lwr_description/meshes/link_3.dae"/>
			</geometry>
		</visual>
	</link>

	<joint name="Joint_4" type="revolute">
		<origin xyz="0 0 0.20" rpy="0 0 0"/>
		<axis xyz="0 1 0"/>
		<limit lower="${-120 * M_PI / 180}" upper="${120 * M_PI / 180}" effort="100" velocity="${velocity_scale * 128 * M_PI / 180}" />
		<parent link="${name}_3_link"/>
		<child link="${name}_4_link"/>
	</joint>

	<link name="${name}_4_link">
		<visual>
			<origin xyz="0 0 0.0" rpy="0 0 ${M_PI}"/>
			<geometry>
				<mesh filename="package://lwr_description/meshes/link_4.dae"/>
			</geometry>
		</visual>
	</link>

	<joint name="Joint_5" type="revolute">
		<origin xyz="0 0 0.20" rpy="0 0 0"/>
		<axis xyz="0 0 1"/>
		<limit lower="${-170 * M_PI / 180}" upper="${170 * M_PI / 180}" effort="100" velocity="${velocity_scale * 204 * M_PI / 180}" />
		<parent link="${name}_4_link"/>
		<child link="${name}_5_link"/>
	</joint>

	<link name="${name}_5_link">
		<visual>
			<origin xyz="0 0 -0.008" rpy="0 0 ${M_PI}"/>
			<geometry name="${name}_5_geom">
				<mesh filename="package://lwr_description/meshes/link_5.dae"/>
			</geometry>
		</visual>
	</link>

	<joint name="Joint_6" type="revolute">
		<origin xyz="0 0 0.19" rpy="0 0 0"/>
		<axis xyz="0 -1 0"/>
		<limit lower="${-120 * M_PI / 180}" upper="${120 * M_PI / 180}" effort="38" velocity="${velocity_scale * 184 * M_PI / 180}" />
		<parent link="${name}_5_link"/>
		<child link="${name}_6_link"/>
	</joint>

	<link name="${name}_6_link">
		<visual>
			<origin xyz="0 0 0" rpy="0 0 ${M_PI}"/>
			<geometry>
				<mesh filename="package://lwr_description/meshes/link_6.dae"/>
			</geometry>
		</visual>
	</link>

	<joint name="Joint_7" type="revolute">
		<origin xyz="0 0 0.078" rpy="0 0 0"/>
		<axis xyz="0 0 1"/>
		<limit lower="${-170 * M_PI / 180}" upper="${170 * M_PI / 180}" effort="38" velocity="${velocity_scale * 184 * M_PI / 180}" />
		<parent link="${name}_6_link"/>
		<child link="${name}_7_link"/>
	</joint>

	<link name="${name}_7_link">
		<visual>
			<origin xyz="0 0 0" rpy="0 0 ${M_PI}"/>
			<geometry>
				<mesh filename="package://lwr_description/meshes/link_7.dae"/>
			</geometry>
		</visual>
	</link>

</robot>